<?xml version='1.0'?>

<robot name="my_robot" xmlns:xacro="http://www.ros.org/wiki/xacro">
  <!--<xacro:include filename="$(find my_robot)/urdf/my_robot.gazebo" />-->

  <link name="robot_footprint"></link>

  <joint name="robot_footprint_joint" type="fixed">
    <origin xyz="0 0 0" rpy="0 0 0" />
    <parent link="robot_footprint"/>
    <child link="chassis" />
  </joint>

  <link name='chassis'>
    <pose>0 0 0.1 0 0 0</pose>

    <inertial>
      <mass value="10.0"/>
      <origin xyz="0.0 0 0" rpy=" 0 0 0"/>
      <inertia
          ixx="0.1" ixy="0" ixz="0"
          iyy="0.1" iyz="0"
          izz="0.1"
      />
    </inertial>

    <collision name='collision'>
      <origin xyz="0 0 0" rpy=" 0 0 0"/> 
      <geometry>
        <box size=".4 .2 .1"/>
      </geometry>
    </collision>

    <visual name='chassis_visual'>
      <origin xyz="0 0 0" rpy=" 0 0 0"/>
      <geometry>
        <box size=".4 .2 .1"/>
      </geometry>
    </visual>
  </link>

  <link name='left_front_wheel_passive'>
     <inertial>
      <mass value="1.0"/>
      <origin xyz="0.15 0.15 0" rpy=" 0 0 0"/>
      <inertia
          ixx="0.1" ixy="0" ixz="0"
          iyy="0.1" iyz="0"
          izz="0.1"
      />
    </inertial>

    <collision name='lfwp_collision'>
      <origin xyz="0.15 0.15 0" rpy="0 0 0"/>
      <geometry>
        <sphere size="0.05"/>
      </geometry>
    </collision>

    <visual name='lfwp_visual'>
      <origin xyz="0.15 0.15 0" rpy="0 0 0"/>
      <geometry>
        <sphere size="0.05"/>
      </geometry>
    </visual>
  </link>

  <link name='right_front_wheel_passive'>
     <inertial>
      <mass value="1.0"/>
      <origin xyz="0.15 -0.15 0" rpy=" 0 0 0"/>
      <inertia
          ixx="0.1" ixy="0" ixz="0"
          iyy="0.1" iyz="0"
          izz="0.1"
      />
    </inertial>

    <collision name='rfwp_collision'>
      <origin xyz="0.15 -0.15 0" rpy="0 0 0"/>
      <geometry>
        <sphere size="0.05"/>
      </geometry>
    </collision>

    <visual name='rfwp_visual'>
      <origin xyz="0.15 -0.15 0" rpy="0 0 0"/>
      <geometry>
        <sphere size="0.05"/>
      </geometry>
    </visual>
  </link>

  <link name='left_rear_wheel_passive'>
     <inertial>
      <mass value="1.0"/>
      <origin xyz="-0.15 0.15 0" rpy=" 0 0 0"/>
      <inertia
          ixx="0.1" ixy="0" ixz="0"
          iyy="0.1" iyz="0"
          izz="0.1"
      />
    </inertial>

    <collision name='lrwp_collision'>
      <origin xyz="-0.15 0.15 0" rpy="0 0 0"/>
      <geometry>
        <sphere size="0.05"/>
      </geometry>
    </collision>

    <visual name='lrwp_visual'>
      <origin xyz="-0.15 0.15 0" rpy="0 0 0"/>
      <geometry>
        <sphere size="0.05"/>
      </geometry>
    </visual>
  </link>

  <link name='right_rear_wheel_passive'>
     <inertial>
      <mass value="1.0"/>
      <origin xyz="-0.15 -0.15 0" rpy=" 0 0 0"/>
      <inertia
          ixx="0.1" ixy="0" ixz="0"
          iyy="0.1" iyz="0"
          izz="0.1"
      />
    </inertial>

    <collision name='rrwp_collision'>
      <origin xyz="-0.15 -0.15 0" rpy="0 0 0"/>
      <geometry>
        <sphere size="0.05"/>
      </geometry>
    </collision>

    <visual name='rrwp_visual'>
      <origin xyz="-0.15 -0.15 0" rpy="0 0 0"/>
      <geometry>
        <sphere size="0.05"/>
      </geometry>
    </visual>
  </link>

  <link name='left_mid_wheel_drive'>
     <inertial>
      <mass value="5.0"/>
      <origin xyz="0.0 0.15 0" rpy=" 0 0 0"/>
      <inertia
          ixx="0.1" ixy="0" ixz="0"
          iyy="0.1" iyz="0"
          izz="0.1"
      />
    </inertial>

    <collision name='lmwd_collision'>
      <origin xyz="0.0 0.15 0" rpy="0 0 0"/>
      <geometry>
        <sphere size="0.05"/>
      </geometry>
    </collision>

    <visual name='lmwd_visual'>
      <origin xyz="0.0 0.15 0" rpy="0 0 0"/>
      <geometry>
        <sphere size="0.05"/>
      </geometry>
    </visual>
  </link>

  <link name='right_mid_wheel_drive'>
     <inertial>
      <mass value="5.0"/>
      <origin xyz="0.0 -0.15 0" rpy=" 0 0 0"/>
      <inertia
          ixx="0.1" ixy="0" ixz="0"
          iyy="0.1" iyz="0"
          izz="0.1"
      />
    </inertial>

    <collision name='rmwd_collision'>
      <origin xyz="0.0 -0.15 0" rpy="0 0 0"/>
      <geometry>
        <sphere size="0.05"/>
      </geometry>
    </collision>

    <visual name='rmwd_visual'>
      <origin xyz="0.0 -0.15 0" rpy="0 0 0"/>
      <geometry>
        <sphere size="0.05"/>
      </geometry>
    </visual>
  </link>

  <joint type="continuous" name="left_front">
    <origin xyz="0.15 0.15 0" rpy="0 0 0"/>
    <child link="left_front_wheel_passive"/>
    <parent link="chassis"/>
    <axis xyz="0 1 0" rpy="0 0 0"/>
    <limit effort="10000" velocity="1000"/>
    <dynamics damping="1.0" friction="1.0"/>
  </joint>

  <joint type="continuous" name="right_front">
    <origin xyz="0.15 -0.15 0" rpy="0 0 0"/>
    <child link="right_front_wheel_passive"/>
    <parent link="chassis"/>
    <axis xyz="0 1 0" rpy="0 0 0"/>
    <limit effort="10000" velocity="1000"/>
    <dynamics damping="1.0" friction="1.0"/>
  </joint>

  <joint type="continuous" name="left_rear">
    <origin xyz="-0.15 0.15 0" rpy="0 0 0"/>
    <child link="left_rear_wheel_passive"/>
    <parent link="chassis"/>
    <axis xyz="0 1 0" rpy="0 0 0"/>
    <limit effort="10000" velocity="1000"/>
    <dynamics damping="1.0" friction="1.0"/>
  </joint>

  <joint type="continuous" name="right_rear">
    <origin xyz="-0.15 -0.15 0" rpy="0 0 0"/>
    <child link="right_rear_wheel_passive"/>
    <parent link="chassis"/>
    <axis xyz="0 1 0" rpy="0 0 0"/>
    <limit effort="10000" velocity="1000"/>
    <dynamics damping="1.0" friction="1.0"/>
  </joint>

  <joint type="continuous" name="left_drive">
    <origin xyz="0 0.15 0" rpy="0 0 0"/>
    <child link="left_front_wheel_passive"/>
    <parent link="chassis"/>
    <axis xyz="0 1 0" rpy="0 0 0"/>
    <limit effort="10000" velocity="1000"/>
    <dynamics damping="1.0" friction="1.0"/>
  </joint>

  <joint type="continuous" name="right_drive">
    <origin xyz="0 -0.15 0" rpy="0 0 0"/>
    <child link="right_front_wheel_passive"/>
    <parent link="chassis"/>
    <axis xyz="0 1 0" rpy="0 0 0"/>
    <limit effort="10000" velocity="1000"/>
    <dynamics damping="1.0" friction="1.0"/>
  </joint>
</robot>
